Workbook

Sheet Hướng dẫn
A1: TEST CASE TEMPLATE
A2: Bộ template kiểm thử phần mềm (Theo chuẩn IEEE 829)
A4: Dự án | B4: Ghost Admin CMS
A5: Version | B5: v1.0 / Sprint 1
A6: Nhóm tạo | B6: Code4App
A7: Ngày tạo | B7: 46162
A8: Lần cập nhật | B8: 46163
A9: Trạng thái | B9: Draft / Active / Archived
A11: CÁC SHEET TRONG WORKBOOK NÀY
A12: Hướng dẫn | B12: Sheet này – hướng dẫn sử dụng và thông tin dự án
A13: Test Cases | B13: CHÍNH – Bảng test cases đầy đủ, có Data Validation và màu trạng thái
A14: Bug Report | B14: Báo cáo lỗi liên kết trực tiếp với test case ID
A15: Dashboard | B15: Thống kê tự động: Pass Rate, Coverage, Bug count theo module
A16: Dropdowns | B16: Bảng dữ liệu nguồn cho các dropdown validation
A18: HƯỚNG DẪN SỬ DỤNG
A19: Bước 1 | B19: Điền thông tin dự án vào bảng thông tin ở trên (ô màu xám)
A20: Bước 2 | B20: Vào sheet Test Cases để viết test case. Dùng dropdown để chọn Status, Priority, Severity
A21: Bước 3 | B21: Mỗi module nên dùng 1 màu Module_ID để dễ nhận biết khi filter
A22: Bước 4 | B22: Khi thực thi, điền 'Actual Result' và chọn Status. Dashboard tự cập nhật
A23: Bước 5 | B23: Khi phát hiện bug, điền vào sheet Bug Report và liên kết TC ID
A24: Bước 6 | B24: Dùng Auto Filter (Ctrl+Shift+L) để lọc theo Module, Priority, Status
A25: Lưu ý | B25: KHÔNG xóa hàng tiêu đề màu xanh. Chỉ thêm dữ liệu từ hàng 4 trở đi

Sheet Test Cases
A1: TEST CASE SUITE – Ghost Admin CMS
A2: Dự án: Ghost Admin CMS | Version: v1.0 | Sprint: Sprint 1 | H2: Người tạo: QA Team | Ngày tạo: [DD/MM/YYYY] | N2: Tổng TC: 52
A3: TC ID | B3: Tiêu đề Test Case | C3: Module | D3: Priority | E3: Severity | F3: Loại Test | G3: Preconditions (Điều kiện tiên quyết) | H3: Test Steps (Các bước thực hiện) | I3: Test Data (Dữ liệu đầu vào) | J3: Expected Result (Kết quả mong đợi) | K3: Actual Result (Kết quả thực tế) | L3: Status | M3: Ngày thực hiện | N3: Người thực hiện | O3: Req ID | P3: Automation? | Q3: Ghi chú
A4: TC_AUTH_001 | B4: Hiển thị form đăng nhập khi chưa xác thực | C4: Authentication | D4: Critical | E4: Critical | F4: Functional | G4: Người dùng chưa đăng nhập Browser đang mở | H4: 1. Mở browser 2. Truy cập URL: /ghost | I4: URL: /ghost Trạng thái: chưa đăng nhập | J4: Trang login hiển thị đầy đủ Có trường nhập Email và Password Nút Sign In hiển thị và clickable Link "Forgot?" hiển thị bên dưới form Logo Ghost hiển thị phía trên form | L4: Pass | N4: Bùi Văn Nhớ | O4: REQ-AUTH-001 | P4: Có | Q4: Điều kiện tiên quyết của mọi TC auth
A5: TC_AUTH_002 | B5: Đăng nhập thành công với email và password hợp lệ | C5: Authentication | D5: Critical | E5: Critical | F5: Positive | G5: Trang login đang mở (/ghost) Tài khoản admin hợp lệ tồn tại trong hệ thống | H5: 1. Nhập Email: khaih3222@gmail.com 2. Nhập Password: Vietkhai1108. 3. Click nút "Sign In" | I5: Email: khaih3222@gmail.com Password:Vietkhai1108. | J5: Hệ thống chuyển hướng sang trang Dashboard (/ghost/#/dashboard) Thanh điều hướng trái hiển thị đầy đủ menu Tên người dùng hiển thị trên avatar góc trái dưới Không có error message nào hiển thị | L5: Pass | O5: REQ-AUTH-002 | P5: Có | Q5: Happy path – baseline
A6: TC_AUTH_003 | B6: Đăng nhập thất bại – sai mật khẩu | C6: Authentication | D6: High | E6: High | F6: Negative | G6: Trang login đang mở Tài khoản admin@ghost.local tồn tại | H6: 1. Nhập Email: khaih3222@gmail.com 2. Nhập Password: SaiPassword123 3. Click nút "Sign In" | I6: Email: khaih3222@gmail.com Password: SaiPassword123 (sai) | J6: Trang KHÔNG chuyển hướng, vẫn ở trang login Hiển thị thông báo lỗi: "There is no user with that email address." hoặc "your password is incorrect" | L6: Pass | O6: REQ-AUTH-002 | P6: Có | Q6: Kiểm tra không tiết lộ nguyên nhân thất bại
A7: TC_AUTH_004 | B7: Đăng nhập thất bại – để trống Email | C7: Authentication | D7: High | E7: Medium | F7: Negative | G7: Trang login đang mở | H7: 1. Để trống trường Email 2. Nhập Password: Vietkhai1108. 3. Click nút "Sign In" | I7: Email: (trống) Password:Vietkhai1108. | J7: Trang KHÔNG chuyển hướng Hiển thị thông báo validation lỗi trường Email Field Email được highlight lỗi | L7: Pass | O7: REQ-AUTH-002 | P7: Có | Q7: Validation trường bắt buộc
A8: TC_AUTH_005 | B8: Đăng nhập thất bại – để trống Password | C8: Authentication | D8: High | E8: Medium | F8: Negative | G8: Trang login đang mở | H8: 1. Nhập Email: khaih3222@gmail.com 2. Để trống trường Password 3. Click nút "Sign In" | I8: Email: khaih3222@gmail.com Password: (trống) | J8: Trang KHÔNG chuyển hướng Hiển thị thông báo validation lỗi trường Password Field Password được highlight lỗi | L8: Not Executed | O8: REQ-AUTH-002 | P8: Có
A9: TC_AUTH_006 | B9: Xác minh tài khoản qua mã email (thiết bị mới) | C9: Authentication | D9: High | E9: High | F9: Positive | G9: Tài khoản hợp lệ, đăng nhập từ thiết bị/trình duyệt mới Hệ thống yêu cầu xác minh thêm | H9: 1. Đăng nhập với email/password hợp lệ từ thiết bị mới 2. Quan sát màn hình yêu cầu mã xác minh 3. Kiểm tra hộp thư email đã đăng ký 4. Nhập mã xác minh hợp lệ 5. Click Submit | I9: Email đã đăng ký: khaih3222@gmail.com Mã xác minh: lấy từ email | J9: Form nhập mã xác minh hiển thị sau đăng nhập Email xác minh được gửi tới địa chỉ đã đăng ký Nhập mã hợp lệ → Đăng nhập thành công, vào Dashboard Nhập mã không hợp lệ → Hiển thị thông báo lỗi phù hợp | L9: Pass | O9: REQ-AUTH-003 | P9: Không | Q9: Chỉ trigger khi đăng nhập thiết bị mới
A10: TC_AUTH_007 | B10: Quên mật khẩu – gửi link reset qua email | C10: Authentication | D10: High | E10: High | F10: Positive | G10: Trang login đang mở Email admin@ghost.local đã đăng ký trong hệ thống | H10: 1. Click link "Forgot?" trên trang login 2. Form nhập email hiển thị 3. Nhập Email: khaih3222@gmail.com 4. Click "Send reset link" | I10: Email: khaih3222@gmail.com | J10: Form nhập email reset mật khẩu hiển thị sau click "Forgot?" Thông báo xác nhận "Email sent!" hiển thị Email chứa link đặt lại mật khẩu được gửi tới hộp thư | L10: Pass | O10: REQ-AUTH-004 | P10: Có
A11: TC_AUTH_008 | B11: Quên mật khẩu – link reset có thời hạn (expiry) | C11: Authentication | D11: Medium | E11: Medium | F11: Boundary | G11: Đã request reset link và nhận được email Link đã quá hạn (>24h) | H11: 1. Mở email chứa link reset mật khẩu cũ 2. Click vào link reset đã quá hạn 3. Quan sát trang hiển thị | I11: Link reset password đã hết hạn | J11: Hệ thống hiển thị thông báo link đã hết hạn hoặc không hợp lệ Không cho phép đặt mật khẩu mới Có hướng dẫn để request link mới | L11: Not Executed | O11: REQ-AUTH-004 | P11: Không | Q11: Security boundary – link expiry
A12: TC_AUTH_009 | B12: Đăng xuất – session bị xóa và redirect về login | C12: Authentication | D12: High | E12: High | F12: Positive | G12: User đã đăng nhập thành công Đang ở trang Dashboard | H12: 1. Click avatar/tên người dùng góc trái dưới 2. Menu dropdown xuất hiện 3. Click "Sign Out" | I12: N/A | J12: Hệ thống đăng xuất và redirect về trang login /ghost Session/token bị xóa Truy cập lại /ghost/#/dashboard → redirect về trang login Trang login hiển thị trống, không prefill thông tin cũ | L12: Not Executed | O12: REQ-AUTH-005 | P12: Có
A13: TC_AUTH_010 | B13: Truy cập URL admin khi chưa đăng nhập – redirect login | C13: Authentication | D13: High | E13: High | F13: Security | G13: User chưa đăng nhập hoặc vừa đăng xuất | H13: 1. Trực tiếp nhập URL: /ghost/#/posts 2. Nhấn Enter 3. Quan sát kết quả | I13: URL: /ghost/#/posts URL: /ghost/#/settings URL: /ghost/#/members | J13: Hệ thống KHÔNG cho phép truy cập trang admin Redirect về trang login /ghost Không có nội dung admin nào hiển thị cho user chưa xác thực | L13: Not Executed | O13: REQ-NFR-004 | P13: Có | Q13: Security – protected route access control
A14: TC_DASH_001 | B14: Hiển thị trang Dashboard đầy đủ sau đăng nhập | C14: Dashboard | D14: Critical | E14: Critical | F14: Positive | G14: User đã đăng nhập thành công | H14: 1. Thực hiện đăng nhập thành công 2. Quan sát trang Dashboard (/ghost/#/dashboard) | I14: Tài khoản: khaih3222@gmail.com | J14: Trang Dashboard hiển thị đầy đủ sau đăng nhập Thanh điều hướng trái hiển thị: Posts, Pages, Tags, Members, Settings Khu vực nội dung chính hiển thị widget thống kê Không có lỗi JS hay lỗi giao diện nào | L14: Pass | O14: REQ-DASH-001 | P14: Có
A15: TC_DASH_002 | B15: Dashboard tải trong vòng 3 giây | C15: Dashboard | D15: High | E15: Medium | F15: Performance | G15: User đã đăng nhập Kết nối mạng thông thường (không throttle) | H15: 1. Mở DevTools → Network tab 2. Thực hiện đăng nhập 3. Đo thời gian load trang Dashboard 4. Kiểm tra tổng load time | I15: Công cụ: Chrome DevTools → Network | J15: Trang Dashboard load hoàn toàn trong vòng 3 giây Không có request nào bị timeout Các widget thống kê hiển thị đầy đủ dữ liệu | L15: Not Executed | O15: REQ-NFR-001 | P15: Không | Q15: Đo bằng DevTools Network tab
A16: TC_POST_001 | B16: Xem danh sách bài viết tại menu Posts | C16: Posts | D16: Critical | E16: Critical | F16: Positive | G16: User đã đăng nhập Có ít nhất 1 bài viết trong hệ thống | H16: 1. Click menu "Posts" ở thanh điều hướng trái 2. Quan sát trang danh sách bài viết | I16: N/A | J16: Tab "All Posts" hiển thị Danh sách bài viết hiển thị với tiêu đề, trạng thái, ngày tạo/cập nhật Có bộ lọc theo trạng thái: All, Draft, Published, Scheduled Có ô tìm kiếm bài viết theo tiêu đề Số lượng bài viết hiển thị chính xác | L16: Not Executed | O16: REQ-POST-001 | P16: Có
A17: TC_POST_002 | B17: Lọc bài viết theo trạng thái Draft / Published | C17: Posts | D17: High | E17: Medium | F17: Positive | G17: User đã đăng nhập Có bài viết ở trạng thái Draft và Published | H17: 1. Vào menu Posts 2. Click filter "Draft" → quan sát 3. Click filter "Published" → quan sát 4. Click filter "All" → quan sát | I17: Filter options: All / Draft / Published / Scheduled | J17: Filter "Draft": chỉ hiển thị bài viết trạng thái Draft Filter "Published": chỉ hiển thị bài viết đã xuất bản Filter "All": hiển thị tất cả bài viết Số lượng bài viết khớp với thực tế | L17: Not Executed | O17: REQ-POST-001 | P17: Có
A18: TC_POST_003 | B18: Tìm kiếm bài viết theo tiêu đề | C18: Posts | D18: Medium | E18: Medium | F18: Positive | G18: User đã đăng nhập Có bài viết tiêu đề "Hướng dẫn Ghost CMS" | H18: 1. Vào menu Posts 2. Click vào ô tìm kiếm 3. Nhập: "Hướng dẫn" 4. Quan sát kết quả | I18: Từ khóa tìm kiếm: "Hướng dẫn" | J18: Kết quả tìm kiếm hiển thị real-time Chỉ hiển thị bài viết có tiêu đề chứa "Hướng dẫn" Xóa từ khóa → hiển thị lại toàn bộ danh sách | L18: Not Executed | O18: REQ-POST-001 | P18: Có
A19: TC_POST_004 | B19: Tạo bài viết mới – mở editor trống | C19: Posts | D19: Critical | E19: Critical | F19: Positive | G19: User đã đăng nhập Đang ở trang danh sách Posts | H19: 1. Click nút "New Post" (góc trên phải) 2. Quan sát trang editor mở ra | I19: N/A | J19: Editor bài viết trống mở ra Toolbar định dạng đầy đủ hiển thị (Bold, Italic, Link, Heading, Image...) Trường tiêu đề có placeholder "Post title" Vùng nội dung chính có thể nhập liệu Bài viết tự động lưu dưới dạng Draft | L19: Not Executed | O19: REQ-POST-002 | P19: Có
A20: TC_POST_005 | B20: Soạn thảo nội dung – nhập tiêu đề và nội dung | C20: Posts | D20: High | E20: High | F20: Positive | G20: Đang ở editor bài viết mới hoặc bài viết Draft | H20: 1. Nhập tiêu đề: "Test Post từ Ghost QA" 2. Click vào vùng nội dung 3. Nhập nội dung bài viết 4. Dùng toolbar: bôi đậm một đoạn text 5. Chèn heading H2 6. Chờ 3 giây | I20: Tiêu đề: "Test Post từ Ghost QA" Nội dung: đoạn văn bản sample Formatting: Bold, H2 | J20: Tiêu đề hiển thị trong trường Post title Nội dung hiển thị đúng trong editor Formatting Bold và H2 áp dụng đúng Auto-save xuất hiện ("Saved") sau khi ngừng nhập | L20: Pass | M20: 46180 | N20: Trần Trung Kiên | O20: REQ-POST-003 | P20: Có
A21: TC_POST_006 | B21: Cấu hình Post Settings – URL slug, Tags, Excerpt | C21: Posts | D21: High | E21: Medium | F21: Positive | G21: Đang trong editor bài viết Đã có nội dung tiêu đề | H21: 1. Click biểu tượng bánh răng (⚙) bên phải toolbar 2. Sidebar cài đặt mở ra 3. Thay đổi URL slug thành: "test-post-ghost-qa" 4. Gán tag: "QA Testing" 5. Nhập Excerpt: "Bài viết kiểm thử Ghost CMS" 6. Click ra ngoài để lưu | I21: Slug: test-post-ghost-qa Tag: QA Testing Excerpt: Bài viết kiểm thử Ghost CMS | J21: Sidebar cài đặt hiển thị đầy đủ: URL slug, Tags, Author, Excerpt, Feature image URL slug cập nhật theo giá trị mới Tag "QA Testing" được gán vào bài viết Excerpt được lưu thành công | L21: Not Executed | O21: REQ-POST-004 | P21: Có
A22: TC_POST_007 | B22: Publish bài viết – xuất bản ngay lập tức | C22: Posts | D22: Critical | E22: Critical | F22: Positive | G22: Bài viết Draft đã có tiêu đề và nội dung Đang ở editor bài viết | H22: 1. Click nút "Publish" ở góc trên phải 2. Popup xác nhận xuất bản hiển thị 3. Chọn "Publish immediately" 4. Click "Publish" trong popup | I22: Bài viết: "Test Post từ Ghost QA" Tùy chọn: Publish immediately | J22: Popup xác nhận hiển thị với tùy chọn publish ngay hoặc đặt lịch Sau click Publish: trạng thái đổi thành "Published" Badge "Published" xuất hiện trên editor Bài viết xuất hiện trong danh sách filter "Published" | L22: Not Executed | O22: REQ-POST-005 | P22: Có | Q22: Critical path – content publication
A23: TC_POST_008 | B23: Đặt lịch xuất bản (Schedule) bài viết | C23: Posts | D23: High | E23: Medium | F23: Positive | G23: Bài viết Draft đang mở trong editor | H23: 1. Click nút "Publish" 2. Chọn "Schedule for later" 3. Đặt ngày giờ: ngày mai +1 tiếng 4. Click "Schedule" | I23: Ngày giờ đặt lịch: [ngày mai] [giờ hiện tại + 1h] | J23: Trạng thái bài viết đổi thành "Scheduled" Ngày giờ xuất bản hiển thị trong editor Bài viết xuất hiện trong filter "Scheduled" Vào đúng giờ hệ thống tự publish | L23: Not Executed | O23: REQ-POST-005 | P23: Không | Q23: Scheduled publish – cần đợi đúng giờ
A24: TC_POST_009 | B24: Xem danh sách bài viết Published qua bộ lọc | C24: Posts | D24: Medium | E24: Medium | F24: Positive | G24: Có ít nhất 1 bài viết Published trong hệ thống | H24: 1. Vào menu Posts 2. Click filter "Published" 3. Quan sát danh sách | I24: Filter: Published | J24: Chỉ hiển thị bài viết có trạng thái Published Số lượng bài viết khớp với thực tế Mỗi bài viết hiển thị ngày xuất bản | L24: Not Executed | O24: REQ-POST-006 | P24: Có
A25: TC_POST_010 | B25: Xóa bài viết – có popup xác nhận trước khi xóa | C25: Posts | D25: High | E25: High | F25: Positive | G25: Có bài viết "Test Post để xóa" trong hệ thống User đang ở editor bài viết đó | H25: 1. Mở bài viết cần xóa trong editor 2. Click biểu tượng bánh răng (⚙) 3. Scroll xuống → Click "Delete this post" 4. Popup xác nhận xóa xuất hiện 5. Click "Delete" trong popup | I25: Bài viết: "Test Post để xóa" | J25: Popup xác nhận xóa hiển thị với nội dung cảnh báo Sau click Delete: bài viết bị xóa vĩnh viễn Hệ thống redirect về danh sách Posts Bài viết không còn xuất hiện trong danh sách | L25: Not Executed | O25: REQ-POST-007 | P25: Có | Q25: Xác nhận REQ-NFR-010: thao tác xóa phải có dialog
A26: TC_PAGE_001 | B26: Xem danh sách trang tĩnh tại menu Pages | C26: Pages | D26: High | E26: High | F26: Positive | G26: User đã đăng nhập Có ít nhất 1 page trong hệ thống | H26: 1. Click menu "Pages" ở thanh điều hướng trái 2. Quan sát trang danh sách | I26: N/A | J26: Danh sách trang tĩnh (Pages) hiển thị Mỗi page hiển thị: tiêu đề, trạng thái, ngày cập nhật Có bộ lọc theo trạng thái: All, Draft, Published Có ô tìm kiếm page theo tiêu đề | L26: Not Executed | O26: REQ-PAGE-001 | P26: Có
A27: TC_PAGE_002 | B27: Lọc Pages theo trạng thái Draft / Published | C27: Pages | D27: Medium | E27: Medium | F27: Positive | G27: User đã đăng nhập Có page ở cả trạng thái Draft và Published | H27: 1. Vào menu Pages 2. Click filter "Draft" → quan sát 3. Click filter "Published" → quan sát | I27: Filter: Draft, Published | J27: Filter "Draft": chỉ hiển thị page trạng thái Draft Filter "Published": chỉ hiển thị page đã xuất bản Kết quả khớp với số lượng thực tế | L27: Not Executed | O27: REQ-PAGE-001 | P27: Có
A28: TC_PAGE_003 | B28: Tạo Page mới – mở editor và nhập nội dung | C28: Pages | D28: High | E28: High | F28: Positive | G28: User đã đăng nhập Đang ở trang danh sách Pages | H28: 1. Click "New Page" 2. Editor mở ra 3. Nhập tiêu đề: "About Us" 4. Nhập nội dung về trang 5. Chờ 3 giây (auto-save) | I28: Tiêu đề: About Us Nội dung: mô tả trang giới thiệu | J28: Editor trang tĩnh mở ra với giao diện tương tự Posts editor Trường tiêu đề và nội dung hoạt động bình thường Page được lưu tự động dưới dạng Draft Status "Saved" xuất hiện | K28: Hiển thị form tạo page với các trường: Tiêu đề, Nội dung, Slug/URL, Trạng thái | L28: Pass | M28: 46180 | N28: Hoàng Trần Việt Khải | O28: REQ-PAGE-002 | P28: Có
A29: TC_PAGE_004 | B29: Publish Page – xuất bản trang tĩnh | C29: Pages | D29: High | E29: High | F29: Positive | G29: Page "About Us" đang ở trạng thái Draft trong editor | H29: 1. Click nút "Publish" 2. Popup xác nhận hiển thị 3. Click "Publish" trong popup | I29: Page: About Us | J29: Page chuyển trạng thái sang "Published" Badge "Published" hiển thị trên editor Page xuất hiện trong danh sách filter "Published" | L29: Not Executed | O29: REQ-PAGE-002 | P29: Có
A30: TC_TAG_001 | B30: Xem danh sách Tags đầy đủ | C30: Tags | D30: High | E30: High | F30: Positive | G30: User đã đăng nhập Có ít nhất 1 tag trong hệ thống | H30: 1. Click menu "Tags" ở thanh điều hướng trái 2. Quan sát trang danh sách tags | I30: N/A | J30: Danh sách Tags hiển thị đầy đủ Mỗi tag hiển thị: tên, màu sắc (nếu có), số bài viết liên kết Tổng số tags hiển thị chính xác Danh sách cuộn được nếu tags nhiều | L30: Not Executed | O30: REQ-TAG-001 | P30: Có
A31: TC_TAG_002 | B31: Tạo Tag mới với tên, màu sắc và mô tả | C31: Tags | D31: High | E31: High | F31: Positive | G31: User đã đăng nhập Đang ở trang danh sách Tags | H31: 1. Click "New Tag" 2. Nhập Tên tag: "Ghost QA" 3. Chọn màu sắc: #E74C3C 4. Nhập mô tả: "Tag dùng cho kiểm thử" 5. Click "Save" | I31: Tên: Ghost QA Màu: #E74C3C Mô tả: Tag dùng cho kiểm thử | J31: Form tạo tag hiển thị đầy đủ: tên, color picker, mô tả Sau Save: tag "Ghost QA" xuất hiện trong danh sách Màu sắc và mô tả hiển thị đúng Tag có thể được gán cho bài viết | L31: Not Executed | O31: REQ-TAG-002 | P31: Có
A32: TC_TAG_003 | B32: Tạo Tag với tên rỗng – validation lỗi | C32: Tags | D32: Medium | E32: Medium | F32: Negative | G32: Đang ở form tạo tag mới | H32: 1. Để trống trường Tên tag 2. Click "Save" | I32: Tên tag: (trống) | J32: Hệ thống KHÔNG tạo tag mới Hiển thị thông báo lỗi: trường tên là bắt buộc Form vẫn mở để người dùng nhập lại | L32: Not Executed | O32: REQ-TAG-002 | P32: Có | Q32: Validation trường bắt buộc
A33: TC_TAG_004 | B33: Sửa thông tin Tag – cập nhật tên và màu sắc | C33: Tags | D33: Medium | E33: Medium | F33: Positive | G33: Tag "Ghost QA" đã tồn tại trong hệ thống | H33: 1. Click vào tag "Ghost QA" trong danh sách 2. Form chỉnh sửa hiển thị 3. Đổi tên thành: "Ghost QA Updated" 4. Đổi màu thành: #2ECC71 5. Click "Save" | I33: Tên mới: Ghost QA Updated Màu mới: #2ECC71 | J33: Form chỉnh sửa hiển thị thông tin hiện tại của tag Sau Save: tag cập nhật thành "Ghost QA Updated" Màu sắc mới hiển thị trong danh sách Bài viết đã gán tag này không bị ảnh hưởng | K33: Tag có thể cập nhật và sửa được thông tin | L33: Pass | M33: 46180 | N33: Hoàng Trần Việt Khải | O33: REQ-TAG-003 | P33: Có
A34: TC_TAG_005 | B34: Xóa Tag – có popup xác nhận, bài viết không bị ảnh hưởng | C34: Tags | D34: Medium | E34: Medium | F34: Positive | G34: Tag "Ghost QA Updated" tồn tại Có bài viết đã gán tag này | H34: 1. Click vào tag cần xóa 2. Click "Delete tag" 3. Popup xác nhận xuất hiện 4. Click "Delete" | I34: Tag: Ghost QA Updated | J34: Popup xác nhận xóa hiển thị trước khi thực hiện Sau Delete: tag bị xóa khỏi hệ thống Tag không còn trong danh sách Bài viết đã gán tag này vẫn tồn tại (tag chỉ bị tách ra) | L34: Not Executed | O34: REQ-TAG-004 | P34: Có | Q34: REQ-NFR-010: phải có confirmation dialog
A35: TC_TAG_006 | B35: Gán Tag cho bài viết qua Post Settings | C35: Tags | D35: High | E35: Medium | F35: Positive | G35: Tag "Ghost QA" đã tồn tại Đang ở editor một bài viết | H35: 1. Mở Post Settings sidebar (⚙) 2. Click vào trường Tags 3. Gõ "Ghost QA" → chọn tag từ dropdown 4. Click Publish/Update | I35: Tag gán: Ghost QA | J35: Tag "Ghost QA" xuất hiện trong trường Tags của bài viết Sau lưu/publish: tag được liên kết với bài viết Bài viết hiển thị đúng số lượng tag trong danh sách Posts | L35: Not Executed | O35: REQ-TAG-002 | P35: Có
A36: TC_MEM_001 | B36: Xem danh sách Members đầy đủ | C36: Members | D36: High | E36: High | F36: Positive | G36: User đã đăng nhập Có ít nhất 1 member trong hệ thống | H36: 1. Click menu "Members" ở thanh điều hướng 2. Quan sát trang danh sách members | I36: N/A | J36: Danh sách Members hiển thị đầy đủ Mỗi member hiển thị: email, tên, ngày tham gia Tổng số members hiển thị chính xác Có phân trang hoặc scroll nếu danh sách dài | L36: Not Executed | O36: REQ-MEM-001 | P36: Có
A37: TC_MEM_002 | B37: Tạo Member thủ công với email hợp lệ | C37: Members | D37: High | E37: High | F37: Positive | G37: User đã đăng nhập Đang ở trang danh sách Members | H37: 1. Click "New Member" 2. Nhập Email: newmember@test.com 3. Nhập Tên: Test Member 4. Click "Save" | I37: Email: newmember@test.com Tên: Test Member | J37: Form tạo member hiển thị đầy đủ (Email, Tên, Labels) Sau Save: member "Test Member" xuất hiện trong danh sách Email newmember@test.com hiển thị đúng | L37: Not Executed | O37: REQ-MEM-002 | P37: Có
A38: TC_MEM_003 | B38: Tạo Member với email không hợp lệ – validation lỗi | C38: Members | D38: High | E38: Medium | F38: Negative | G38: Đang ở form tạo member mới | H38: 1. Nhập Email: khong-phai-email 2. Nhập Tên: Invalid User 3. Click "Save" | I38: Email: khong-phai-email (không đúng định dạng) | J38: Hệ thống KHÔNG tạo member mới Hiển thị thông báo lỗi: email không hợp lệ Field Email được highlight lỗi | L38: Not Executed | O38: REQ-MEM-002 | P38: Có | Q38: Validation format email
A39: TC_MEM_004 | B39: Xem trang chi tiết của một Member | C39: Members | D39: Medium | E39: Medium | F39: Positive | G39: Member "Test Member" tồn tại trong hệ thống | H39: 1. Vào danh sách Members 2. Click vào "Test Member" 3. Quan sát trang profile member | I39: Member: Test Member (newmember@test.com) | J39: Trang profile member mở ra Hiển thị đầy đủ: Email, Tên, Ngày tham gia, Subscriptions Lịch sử hoạt động của member hiển thị Có thể chỉnh sửa thông tin từ trang này | L39: Not Executed | O39: REQ-MEM-003 | P39: Có
A40: TC_MEM_005 | B40: Import Members từ file CSV hợp lệ | C40: Members | D40: Medium | E40: High | F40: Positive | G40: Đã chuẩn bị file members.csv đúng định dạng Ghost File có 5 members với email và tên hợp lệ | H40: 1. Click "Import" trên trang Members 2. Popup upload CSV xuất hiện 3. Chọn file members.csv 4. Xem preview và xác nhận 5. Click Import | I40: File: members.csv Số members: 5 Format: email,name,note | J40: Popup upload CSV hiển thị Preview danh sách members trước khi import Sau import: 5 members được thêm vào danh sách Báo cáo kết quả: "5 imported, 0 errors" | L40: Not Executed | O40: REQ-MEM-004 | P40: Không | Q40: Chuẩn bị file CSV đúng định dạng Ghost
...

Sheet Bug Report
A1: BUG REPORT LOG – Ghost Admin CMS
A2: Danh sách defects phát hiện trong quá trình kiểm thử – Liên kết với Test Case ID
A3: Bug ID | B3: Tiêu đề Bug | C3: Module | D3: Severity | E3: Priority | F3: Môi trường | G3: Linked TC ID | H3: Steps to Reproduce (Bước tái hiện) | I3: Expected Result | J3: Actual Result | K3: Status | L3: Reported By | M3: Reported Date | N3: Fixed Date | O3: Ghi chú

Sheet Dashboard
A1: TEST EXECUTION DASHBOARD
A2: Các chỉ số tự động cập nhật khi điền dữ liệu vào sheet Test Cases và Bug Report
A4: THỐNG KÊ TEST CASES | F4: TC THEO MODULE
A5: Tổng Test Cases | B5: =COUNTA('Test Cases'!A4:A200) -> 52 | F5: Authentication | G5: =COUNTIF('Test Cases'!C4:C200,"Authentication") -> 10 | I5: =COUNTIFS('Test Cases'!C4:C200,"Authentication",'Test Cases'!L4:L200,"Pass") -> 6
A6: Not Executed | B6: =COUNTIF('Test Cases'!L4:L200,"Not Executed") -> 41 | F6: Dashboard | G6: =COUNTIF('Test Cases'!C4:C200,"Dashboard") -> 2 | I6: =COUNTIFS('Test Cases'!C4:C200,"Dashboard",'Test Cases'!L4:L200,"Pass") -> 1
A7: In Progress | B7: =COUNTIF('Test Cases'!L4:L200,"In Progress") -> 0 | F7: Posts | G7: =COUNTIF('Test Cases'!C4:C200,"Posts") -> 10 | I7: =COUNTIFS('Test Cases'!C4:C200,"Posts",'Test Cases'!L4:L200,"Pass") -> 1
A8: PASS | B8: =COUNTIF('Test Cases'!L4:L200,"Pass") -> 11 | F8: Pages | G8: =COUNTIF('Test Cases'!C4:C200,"Pages") -> 4 | I8: =COUNTIFS('Test Cases'!C4:C200,"Pages",'Test Cases'!L4:L200,"Pass") -> 1
A9: FAIL | B9: =COUNTIF('Test Cases'!L4:L200,"Fail") -> 0 | F9: Tags | G9: =COUNTIF('Test Cases'!C4:C200,"Tags") -> 6 | I9: =COUNTIFS('Test Cases'!C4:C200,"Tags",'Test Cases'!L4:L200,"Pass") -> 1
A10: BLOCKED | B10: =COUNTIF('Test Cases'!L4:L200,"Blocked") -> 0 | F10: Members | G10: =COUNTIF('Test Cases'!C4:C200,"Members") -> 8 | I10: =COUNTIFS('Test Cases'!C4:C200,"Members",'Test Cases'!L4:L200,"Pass") -> 0
A11: SKIPPED | B11: =COUNTIF('Test Cases'!L4:L200,"Skipped") -> 0 | F11: Settings | G11: =COUNTIF('Test Cases'!C4:C200,"Settings") -> 6 | I11: =COUNTIFS('Test Cases'!C4:C200,"Settings",'Test Cases'!L4:L200,"Pass") -> 0
A12: Pass Rate (%) | B12: =IFERROR(COUNTIF('Test Cases'!L4:L200,"Pass")/MAX(1,COUNTIF('Test Cases'!L4:L200,"Pass")+COUNTIF('Test Cases'!L4:L200,"Fail")),0) -> 1 | F12: Staff/Users | G12: =COUNTIF('Test Cases'!C4:C200,"Staff/Users") -> 6 | I12: =COUNTIFS('Test Cases'!C4:C200,"Staff/Users",'Test Cases'!L4:L200,"Pass") -> 1
A14: THỐNG KÊ BUG | F14: PHÂN LOẠI TC THEO PRIORITY
A15: Tổng Bugs | B15: =COUNTA('Bug Report'!A4:A200) -> 0 | F15: Critical TCs | G15: =COUNTIF('Test Cases'!D4:D200,"Critical") -> 6
A16: Critical | B16: =COUNTIF('Bug Report'!D4:D200,"Critical") -> 0 | F16: High TCs | G16: =COUNTIF('Test Cases'!D4:D200,"High") -> 27
A17: High | B17: =COUNTIF('Bug Report'!D4:D200,"High") -> 0 | F17: Medium TCs | G17: =COUNTIF('Test Cases'!D4:D200,"Medium") -> 19
A18: Medium | B18: =COUNTIF('Bug Report'!D4:D200,"Medium") -> 0 | F18: Low TCs | G18: =COUNTIF('Test Cases'!D4:D200,"Low") -> 0
A19: Low | B19: =COUNTIF('Bug Report'!D4:D200,"Low") -> 0
A20: Open | B20: =COUNTIF('Bug Report'!K4:K200,"Open") -> 0
A21: Fixed | B21: =COUNTIF('Bug Report'!K4:K200,"Fixed") -> 0
A22: Closed | B22: =COUNTIF('Bug Report'!K4:K200,"Closed") -> 0

Sheet Dropdowns
A1: BẢNG THAM CHIẾU – GIÁ TRỊ DROPDOWN
A2: PRIORITY | B2: SEVERITY | C2: STATUS (TC) | D2: STATUS (BUG) | E2: TEST TYPE | F2: BUG PRIORITY | G2: AUTOMATION
A3: Critical | B3: Critical | C3: Not Executed | D3: Open | E3: Positive | F3: P1 – Critical | G3: Có
A4: High | B4: High | C4: In Progress | D4: In Progress | E4: Negative | F4: P2 – High | G4: Không
A5: Medium | B5: Medium | C5: Pass | D5: Fixed | E5: Boundary | F5: P3 – Medium | G5: Một phần
A6: Low | B6: Low | C6: Fail | D6: Reopen | E6: Edge Case | F6: P4 – Low
C7: Blocked | D7: Closed | E7: Performance
C8: Skipped | D8: Rejected | E8: Security
C9: N/A | D9: Deferred | E9: UI
E10: Regression
E11: Smoke
